2025-06-22 21:56:26,205 | INFO | Job #39 started for ZIP: uploads/Screenshot_2025-06-04_221831.png
2025-06-22 21:56:26,220 | ERROR | Sync failed: File is not a zip file
Traceback (most recent call last):
  File "C:\Users\Asus\Projects\zebrasync\core\tasks.py", line 28, in run_sync
    with zipfile.ZipFile(job.src_zip.path) as zf:
         ^^^^^^^^^^^^^^^^^^^^^^^^^^^^^^^^^
  File "C:\Python311\Lib\zipfile.py", line 1302, in __init__
    self._RealGetContents()
  File "C:\Python311\Lib\zipfile.py", line 1369, in _RealGetContents
    raise BadZipFile("File is not a zip file")
zipfile.BadZipFile: File is not a zip file
