2025-06-22 21:57:06,212 | INFO | Job #40 started for ZIP: uploads/sync.py
2025-06-22 21:57:06,238 | ERROR | Sync failed: File is not a zip file
Traceback (most recent call last):
  File "C:\Users\Asus\Projects\zebrasync\core\tasks.py", line 28, in run_sync
    with zipfile.ZipFile(job.src_zip.path) as zf:
         ^^^^^^^^^^^^^^^^^^^^^^^^^^^^^^^^^
  File "C:\Python311\Lib\zipfile.py", line 1302, in __init__
    self._RealGetContents()
  File "C:\Python311\Lib\zipfile.py", line 1369, in _RealGetContents
    raise BadZipFile("File is not a zip file")
zipfile.BadZipFile: File is not a zip file
